/var/spool/torque/mom_priv/jobs/22583551.shared-sched.pace.gatech.edu.SC: line 12: cd: sugar/vipgit/: No such file or directory
sh: /tmp/uniqnodefile: Permission denied
[mpiexec@rich133-c32-28-l.pace.gatech.edu] find_pbs_node_id (tools/bootstrap/external/pbs_launch.c:28): user specified host not in the PBS allocated list
[mpiexec@rich133-c32-28-l.pace.gatech.edu] HYDT_bscd_pbs_launch_procs (tools/bootstrap/external/pbs_launch.c:73): error finding PBS node ID for host rich133-c34-32-l.pace.gatech.edu
[mpiexec@rich133-c32-28-l.pace.gatech.edu] HYDT_bsci_launch_procs (tools/bootstrap/src/bsci_launch.c:17): launcher returned error while launching processes
[mpiexec@rich133-c32-28-l.pace.gatech.edu] HYD_pmci_launch_procs (pm/pmiserv/pmiserv_pmci.c:135): launcher cannot launch processes
[mpiexec@rich133-c32-28-l.pace.gatech.edu] main (ui/mpich/mpiexec.c:340): process manager returned error launching processes
[proxy:0:0@rich133-c32-28-l.pace.gatech.edu] HYDU_sock_connect (utils/sock/sock.c:172): unable to connect from "rich133-c32-28-l.pace.gatech.edu" to "rich133-c32-28-l.pace.gatech.edu" (Connection refused)
[proxy:0:0@rich133-c32-28-l.pace.gatech.edu] main (pm/pmiserv/pmip.c:189): unable to connect to server rich133-c32-28-l.pace.gatech.edu at port 36873 (check for firewalls!)
[mpiexec@rich133-c32-28-l.pace.gatech.edu] find_pbs_node_id (tools/bootstrap/external/pbs_launch.c:28): user specified host not in the PBS allocated list
[mpiexec@rich133-c32-28-l.pace.gatech.edu] HYDT_bscd_pbs_launch_procs (tools/bootstrap/external/pbs_launch.c:73): error finding PBS node ID for host rich133-c34-32-l.pace.gatech.edu
[mpiexec@rich133-c32-28-l.pace.gatech.edu] HYDT_bsci_launch_procs (tools/bootstrap/src/bsci_launch.c:17): launcher returned error while launching processes
[mpiexec@rich133-c32-28-l.pace.gatech.edu] HYD_pmci_launch_procs (pm/pmiserv/pmiserv_pmci.c:135): launcher cannot launch processes
[mpiexec@rich133-c32-28-l.pace.gatech.edu] main (ui/mpich/mpiexec.c:340): process manager returned error launching processes
[proxy:0:0@rich133-c32-28-l.pace.gatech.edu] HYDU_sock_connect (utils/sock/sock.c:172): unable to connect from "rich133-c32-28-l.pace.gatech.edu" to "rich133-c32-28-l.pace.gatech.edu" (Connection refused)
[proxy:0:0@rich133-c32-28-l.pace.gatech.edu] main (pm/pmiserv/pmip.c:189): unable to connect to server rich133-c32-28-l.pace.gatech.edu at port 43193 (check for firewalls!)
[cli_0]: aborting job:
application called MPI_Abort(MPI_COMM_WORLD, 1) - process 0
[cli_1]: aborting job:
application called MPI_Abort(MPI_COMM_WORLD, 1) - process 1
[cli_8]: aborting job:
application called MPI_Abort(MPI_COMM_WORLD, 1) - process 8
[cli_3]: aborting job:
application called MPI_Abort(MPI_COMM_WORLD, 1) - process 3
[cli_5]: aborting job:
application called MPI_Abort(MPI_COMM_WORLD, 1) - process 5
[cli_4]: aborting job:
application called MPI_Abort(MPI_COMM_WORLD, 1) - process 4
[cli_11]: aborting job:
application called MPI_Abort(MPI_COMM_WORLD, 1) - process 11
[cli_2]: aborting job:
application called MPI_Abort(MPI_COMM_WORLD, 1) - process 2
[cli_9]: aborting job:
application called MPI_Abort(MPI_COMM_WORLD, 1) - process 9
[cli_10]: aborting job:
application called MPI_Abort(MPI_COMM_WORLD, 1) - process 10
[cli_12]: aborting job:
application called MPI_Abort(MPI_COMM_WORLD, 1) - process 12
[cli_13]: aborting job:
application called MPI_Abort(MPI_COMM_WORLD, 1) - process 13
Traceback (most recent call last):
  File "single_point.py", line 24, in <module>
    relax_slab_ads.run(fmax=0.05)
  File "/gpfs/pace1/project/chbe-medford/medford-share/gits/frozen/ase_3.13.0/ase/ase/optimize/optimize.py", line 162, in run
    self.set_force_consistent()
  File "/gpfs/pace1/project/chbe-medford/medford-share/gits/frozen/ase_3.13.0/ase/ase/optimize/optimize.py", line 214, in set_force_consistent
    self.atoms.get_potential_energy(force_consistent=True)
  File "/gpfs/pace1/project/chbe-medford/medford-share/gits/frozen/ase_3.13.0/ase/ase/atoms.py", line 680, in get_potential_energy
    self, force_consistent=force_consistent)
  File "/gpfs/pace1/project/chbe-medford/medford-share/gits/frozen/ben_espresso_8_24_2017/espresso/__init__.py", line 2201, in get_potential_energy
    self.update(atoms)
  File "/gpfs/pace1/project/chbe-medford/medford-share/gits/frozen/ben_espresso_8_24_2017/espresso/__init__.py", line 1636, in update
    self.read(atoms)
  File "/gpfs/pace1/project/chbe-medford/medford-share/gits/frozen/ben_espresso_8_24_2017/espresso/__init__.py", line 1752, in read
    self.checkerror()
  File "/gpfs/pace1/project/chbe-medford/medford-share/gits/frozen/ben_espresso_8_24_2017/espresso/__init__.py", line 2319, in checkerror
    raise RuntimeError, msg[:len(msg)-1]
RuntimeError:      Error in routine read_input (2):
     opening input file
